<?xml version="1.0" ?>
<!-- =================================================================================== -->
<!-- |    This document was autogenerated by xacro from model.sdf.xacro                | -->
<!-- |    EDITING THIS FILE BY HAND IS NOT RECOMMENDED                                 | -->
<!-- =================================================================================== -->
<sdf version="1.4">
  <model name="Car" xmlns:xacro="http://www.ros.org/wiki/xacro">
    <static>false</static>
    <link name="chassis">
      <pose>0 0 0.08 0 0 0</pose>
      <collision name="collision">
        <geometry>
          <box>
            <size>0.5 0.5 0.1</size>
          </box>
        </geometry>
      </collision>
      <visual name="visual">
        <geometry>
          <box>
            <size>0.5 0.5 0.1</size>
          </box>
        </geometry>
        <material>
          <script>
            <uri>file://media/materials/scripts/texture.material</uri>
            <name>LandingStation</name>
          </script>
        </material>
      </visual>
      <inertial>
        <mass>50</mass>
        <inertia>
          <ixx>1.08333333333</ixx>
          <iyy>1.08333333333</iyy>
          <izz>2.08333333333</izz>
          <ixy>0</ixy>
          <ixz>0</ixz>
          <iyz>0</iyz>
        </inertia>
      </inertial>
      <collision name="caster_collision">
        <pose>-0.22 0 -0.05 0 0 0</pose>
        <geometry>
          <sphere>
            <radius>0.03</radius>
          </sphere>
        </geometry>
        <surface>
          <friction>
            <ode>
              <mu>0</mu>
              <mu2>0</mu2>
              <slip1>1.0</slip1>
              <slip2>1.0</slip2>
            </ode>
          </friction>
        </surface>
      </collision>
      <visual name="caster_visual">
        <pose>-0.22 0 -0.05 0 0 0</pose>
        <geometry>
          <sphere>
            <radius>0.03</radius>
          </sphere>
        </geometry>
        <material>
          <script>
            <name>Gazebo/Blue</name>
            <uri>__default__</uri>
          </script>
        </material>
      </visual>
    </link>
    <link name="left_wheel">
      <pose>0.2 0.275 0.08 0 1.57079632679 1.57079632679</pose>
      <collision name="left_wheel_collision">
        <geometry>
          <cylinder>
            <radius>0.08</radius>
            <length>0.05</length>
          </cylinder>
        </geometry>
        <surface>
          <friction>
            <ode>
              <mu>1.0</mu>
              <mu2>1.0</mu2>
              <slip1>0.0</slip1>
              <slip2>0.0</slip2>
            </ode>
          </friction>
        </surface>
      </collision>
      <visual name="left_wheel_visual">
        <geometry>
          <cylinder>
            <radius>0.08</radius>
            <length>0.05</length>
          </cylinder>
        </geometry>
        <material>
          <script>
            <name>Gazebo/Black</name>
            <uri>__default__</uri>
          </script>
        </material>
      </visual>
      <inertial>
        <mass>5</mass>
        <inertia>
          <ixx>0.00904166666667</ixx>
          <iyy>0.00904166666667</iyy>
          <izz>0.016</izz>
          <ixy>0</ixy>
          <ixz>0</ixz>
          <iyz>0</iyz>
        </inertia>
      </inertial>
    </link>
    <joint name="left_wheel_hinge" type="revolute">
      <parent>chassis</parent>
      <child>left_wheel</child>
      <pose>0 0 0.025 0 0 0</pose>
      <axis>
        <xyz>0 1 0</xyz>
        <dynamics>
          <damping>1</damping>
        </dynamics>
        <limit>
          <effort>100</effort>
          <velocity>100</velocity>
        </limit>
      </axis>
    </joint>
    <link name="right_wheel">
      <pose>0.2 -0.275 0.08 0 1.57079632679 1.57079632679</pose>
      <collision name="right_wheel_collision">
        <geometry>
          <cylinder>
            <radius>0.08</radius>
            <length>0.05</length>
          </cylinder>
        </geometry>
        <surface>
          <friction>
            <ode>
              <mu>1.0</mu>
              <mu2>1.0</mu2>
              <slip1>0.0</slip1>
              <slip2>0.0</slip2>
            </ode>
          </friction>
        </surface>
      </collision>
      <visual name="right_wheel_visual">
        <geometry>
          <cylinder>
            <radius>0.08</radius>
            <length>0.05</length>
          </cylinder>
        </geometry>
        <material>
          <script>
            <name>Gazebo/Black</name>
            <uri>__default__</uri>
          </script>
        </material>
      </visual>
      <inertial>
        <mass>5</mass>
        <inertia>
          <ixx>0.00904166666667</ixx>
          <iyy>0.00904166666667</iyy>
          <izz>0.016</izz>
          <ixy>0</ixy>
          <ixz>0</ixz>
          <iyz>0</iyz>
        </inertia>
      </inertial>
    </link>
    <joint name="right_wheel_hinge" type="revolute">
      <parent>chassis</parent>
      <child>right_wheel</child>
      <pose>0 0 0.025 0 0 0</pose>
      <axis>
        <xyz>0 1 0</xyz>
        <dynamics>
          <damping>1</damping>
        </dynamics>
        <limit>
          <effort>100</effort>
          <velocity>100</velocity>
        </limit>
      </axis>
    </joint>
  </model>
</sdf>
